// practising error handling
function addTwoNums(a,b) {
    try {
        if(typeof(a) != 'number') {
            throw new ReferenceError('the first argument is not a number')
        } else if (typeof(b) != 'number') {
            throw new ReferenceError('the second argument is not a number')
        } else {
            console.log(a + b)
        }
    } catch(err) {
        console.log("Error!", err)
    }
}
addTwoNums(12,"30")

console.log("The program continues")